Workbook

Sheet Velocity
A26: Sprint | B26: Sprint Start Date | C26: Sprint End Date | D26: Comittment | E26: Unplanned | F26: Done | G26: Done Percentage | H26: Velocity AVG | I26: Total Sprint SP | J26: Carry Over SP | K26: Carry Over Percetage | L26: Capacity SP | M26: Workday % | N26: User Stories Done
A27: Sprint 15 | B27: 46218 | C27: 46231.999 | D27: =SUM('Sprint 15 Jul15-Jul28'!N:N) -> 47 | E27: =SUM('Sprint 15 Jul15-Jul28'!O:O) -> 35 | F27: =SUM('Sprint 15 Jul15-Jul28'!P:P) -> 77 | G27: =F27/D27 -> 1.6382979 | H27: =AVERAGE($F$27:F27) -> 77 | I27: =SUM('Sprint 15 Jul15-Jul28'!I:I) -> 82 | J27: =SUM('Sprint 15 Jul15-Jul28'!J:J) -> 2 | K27: =J27/D27 -> 0.042553191 | L27: =I27-J27 -> 80 | M27: =SUM(Capacity!I21:I31)/SUM(Capacity!A21:A31) -> 0.91818182
A28: Sprint 16 | B28: 46232 | C28: 46245.999 | D28: =SUM('Sprint 16 Jul29-Ago11'!N:N) -> 62 | E28: =SUM('Sprint 16 Jul29-Ago11'!O:O) -> 12 | F28: =SUM('Sprint 16 Jul29-Ago11'!P:P) -> 69 | G28: =F28/D28 -> 1.1129032 | H28: =AVERAGE($F$27:F28) -> 73 | I28: =SUM('Sprint 16 Jul29-Ago11'!I:I) -> 74 | J28: =SUM('Sprint 16 Jul29-Ago11'!J:J) -> 2 | K28: =J28/D28 -> 0.032258065 | L28: =I28-J28 -> 72 | M28: =SUM(Capacity!S21:S31)/SUM(Capacity!A21:A31) -> 0.84545455
A29: Sprint 17 | B29: 46246 | C29: 46259.999 | D29: =SUM('Sprint 17 Ago12-Ago25'!N:N) -> 143 | E29: =SUM('Sprint 17 Ago12-Ago25'!O:O) -> 32 | F29: =SUM('Sprint 17 Ago12-Ago25'!P:P) -> 135 | G29: =F29/D29 -> 0.94405594 | H29: =AVERAGE($F$27:F29) -> 93.666667 | I29: =SUM('Sprint 17 Ago12-Ago25'!I:I) -> 162 | J29: =SUM('Sprint 17 Ago12-Ago25'!J:J) -> 18 | K29: =J29/D29 -> 0.12587413 | L29: =I29-J29 -> 144 | M29: =SUM(Capacity!Y21:Y31)/SUM(Capacity!A21:A31) -> 0.87272727
A30: Sprint 18 | B30: 46260 | C30: 46273.999

Sheet Capacity
G19: Sprint 15 (Jul15-Jul28) | L19: Sprint 16 (Jul29-Ago11) | Q19: Sprint 17 (Ago11-Ago25) | W19: Sprint 18 (Ago26-Sep8)
A20: Working days | B20: Capcity | C20: Location | D20: Developer/Admin | E20: Capacity per day | F20: Capacity per sprint | G20: Holidays | H20: PTO | I20: Working Days | J20: Completed | K20: AVG SP15 | L20: Holidays | M20: PTO | N20: Working Days | O20: Completed | P20: AVG SP16 | Q20: Holidays | R20: PTO | S20: Working Days | T20: Committed | U20: Completed | V20: AVG SP17 | W20: Holidays | X20: PTO | Y20: Working Days | Z20: Capacity | AA20: Comitted | AB20: Completed | AC20: AVG SP18
A21: 10 | B21: 1 | C21: India | D21: Apala Sen | E21: =AVERAGE(K21,P21,V21,AC21) -> 0.76111111 | F21: =E21*A21 -> 7.6111111 | G21: 1 | I21: =A21-H21-G21 -> 9 | J21: 11 | K21: =J21/I21 -> 1.2222222 | N21: =A21-M21-L21 -> 10 | O21: 3 | P21: =O21/N21 -> 0.3 | S21: =A21-Q21-R21 -> 10 | T21: 16 | U21: =27-8 -> 19 | W21: 1 | Y21: =A21-X21-W21 -> 9 | Z21: 12
A22: 10 | B22: 1 | C22: Argentina | D22: Carlos Juarez | E22: =AVERAGE(K22,P22,V22,AC22) -> 0.8 | F22: =E22*A22 -> 8 | I22: =A22-H22-G22 -> 10 | J22: 8 | K22: =J22/I22 -> 0.8 | N22: =A22-M22-L22 -> 10 | O22: 8 | P22: =O22/N22 -> 0.8 | Q22: 1 | R22: 3 | S22: =A22-Q22-R22 -> 6 | T22: 5 | U22: 13 | Y22: =A22-X22-W22 -> 10 | Z22: 8
A23: 10 | B23: 1 | C23: Colombia | D23: Santiago Epalza | E23: =AVERAGE(K23,P23,V23,AC23) -> 0 | F23: =E23*A23 -> 0 | G23: 1 | I23: =A23-H23-G23 -> 9 | J23: 0 | K23: =J23/I23 -> 0 | L23: 1 | N23: =A23-M23-L23 -> 9 | O23: 0 | P23: =O23/N23 -> 0 | Q23: 1 | S23: =A23-Q23-R23 -> 9 | T23: 5 | U23: 8 | X23: 1 | Y23: =A23-X23-W23 -> 9 | Z23: 8
A24: 10 | B24: 1 | C24: Argentina | D24: Tomas Olivera | E24: =AVERAGE(K24,P24,V24,AC24) -> 0.26666667 | F24: =E24*A24 -> 2.6666667 | H24: 1 | I24: =A24-H24-G24 -> 9 | J24: 3 | K24: =J24/I24 -> 0.33333333 | N24: =A24-M24-L24 -> 10 | O24: 2 | P24: =O24/N24 -> 0.2 | Q24: 1 | S24: =A24-Q24-R24 -> 9 | T24: 10 | U24: 10 | Y24: =A24-X24-W24 -> 10 | Z24: 8
A25: 10 | B25: 1 | C25: India | D25: Ataul Khalique | E25: =AVERAGE(K25,P25,V25,AC25) -> 0.41666667 | F25: =E25*A25 -> 4.1666667 | G25: 1 | I25: =A25-H25-G25 -> 9 | J25: 3 | K25: =J25/I25 -> 0.33333333 | N25: =A25-M25-L25 -> 10 | O25: 5 | P25: =O25/N25 -> 0.5 | S25: =A25-Q25-R25 -> 10 | T25: 15 | U25: 22 | W25: 1 | Y25: =A25-X25-W25 -> 9 | Z25: 12
A26: 10 | B26: 1 | C26: Colmbia | D26: Sebastian Perez | E26: =AVERAGE(K26,P26,V26,AC26) -> 0.96666667 | F26: =E26*A26 -> 9.6666667 | G26: 1 | I26: =A26-H26-G26 -> 9 | J26: 3 | K26: =J26/I26 -> 0.33333333 | L26: 1 | M26: 4 | N26: =A26-M26-L26 -> 5 | O26: 8 | P26: =O26/N26 -> 1.6 | Q26: 1 | R26: 9 | S26: =A26-Q26-R26 -> 0 | T26: 0 | U26: 0 | X26: 4 | Y26: =A26-X26-W26 -> 6 | Z26: 5
A27: 10 | B27: 1 | C27: India | D27: Manish Raj | E27: =AVERAGE(K27,P27,V27,AC27) -> 1.3888889 | F27: =E27*A27 -> 13.888889 | G27: 1 | I27: =A27-H27-G27 -> 9 | J27: 16 | K27: =J27/I27 -> 1.7777778 | N27: =A27-M27-L27 -> 10 | O27: 10 | P27: =O27/N27 -> 1 | S27: =A27-Q27-R27 -> 10 | T27: 10 | U27: 12 | W27: 1 | Y27: =A27-X27-W27 -> 9 | Z27: 12
A28: 10 | B28: 1 | C28: India | D28: Mahika Agrawal | E28: =AVERAGE(K28,P28,V28,AC28) -> 0.87222222 | F28: =E28*A28 -> 8.7222222 | G28: 1 | I28: =A28-H28-G28 -> 9 | J28: 4 | K28: =J28/I28 -> 0.44444444 | N28: =A28-M28-L28 -> 10 | O28: 13 | P28: =O28/N28 -> 1.3 | S28: =A28-Q28-R28 -> 10 | T28: 14 | U28: 12 | W28: 1 | Y28: =A28-X28-W28 -> 9 | Z28: 12
A29: 10 | B29: 1 | C29: Colombia | D29: Jacobo Salazar | E29: =AVERAGE(K29,P29,V29,AC29) -> 0.88888889 | F29: =E29*A29 -> 8.8888889 | G29: 1 | I29: =A29-H29-G29 -> 9 | J29: 6 | K29: =J29/I29 -> 0.66666667 | L29: 1 | N29: =A29-M29-L29 -> 9 | O29: 10 | P29: =O29/N29 -> 1.1111111 | Q29: 1 | S29: =A29-Q29-R29 -> 9 | T29: 12 | U29: =12-4 -> 8 | Y29: =A29-X29-W29 -> 10 | Z29: 8
A30: 10 | B30: 1 | C30: Chile | D30: Ignacio Toledo | E30: =AVERAGE(K30,P30,V30,AC30) -> 0.64444444 | F30: =E30*A30 -> 6.4444444 | G30: 1 | I30: =A30-H30-G30 -> 9 | J30: 8 | K30: =J30/I30 -> 0.88888889 | N30: =A30-M30-L30 -> 10 | O30: 4 | P30: =O30/N30 -> 0.4 | S30: =A30-Q30-R30 -> 10 | T30: 20 | U30: =27-5 -> 22 | Y30: =A30-X30-W30 -> 10 | Z30: 12
A31: 10 | B31: 0.5 | C31: USA | D31: Victor Cabrera | E31: =AVERAGE(K31,P31,V31,AC31) -> 0.4 | F31: =E31*A31 -> 4 | I31: =A31-H31-G31 -> 10 | J31: 8 | K31: =J31/I31 -> 0.8 | N31: =A31-M31-L31 -> 10 | O31: 0 | P31: =O31/N31 -> 0 | S31: =A31-Q31-R31 -> 10 | T31: 12 | U31: 12 | W31: 1 | X31: 4 | Y31: =A31-X31-W31 -> 5 | Z31: 8

Sheet Holidays
A1: Type | B1: Date | C1: Day | D1: Impacts Work Calendar | E1: Holiday | F1: Comments | G1: Country | H1: ID
A2: Holiday | B2: 46023 | C2: Thursday | D2: Yes | E2: New Year's Day | G2: Chile | H2: CL
A3: Holiday | B3: 46115 | C3: Friday | D3: Yes | E3: Good Friday | G3: Chile | H3: CL
A4: Holiday | B4: 46116 | C4: Saturday | D4: No | E4: Easter Saturday | G4: Chile | H4: CL
A5: Holiday | B5: 46143 | C5: Friday | D5: Yes | E5: Labour Day | G5: Chile | H5: CL
A6: Holiday | B6: 46163 | C6: Thursday | D6: Yes | E6: Glorias Navales day | G6: Chile | H6: CL
A7: Holiday | B7: 46194 | C7: Sunday | D7: No | E7: National Day of the Indigenous Peoples | G7: Chile | H7: CL
A8: Holiday | B8: 46202 | C8: Monday | D8: Yes | E8: Saint Peter and Saint Paul | G8: Chile | H8: CL
A9: Holiday | B9: 46219 | C9: Thursday | D9: Yes | E9: Day of the Virgin of Carmen | G9: Chile | H9: CL
A10: Holiday | B10: 46249 | C10: Saturday | D10: No | E10: Assumption of Mary | G10: Chile | H10: CL
A11: Holiday | B11: 46283 | C11: Friday | D11: Yes | E11: Independence Day | G11: Chile | H11: CL
A12: Holiday | B12: 46284 | C12: Saturday | D12: No | E12: Day of the Glories of the Army | G12: Chile | H12: CL
A13: Holiday | B13: 46307 | C13: Monday | D13: Yes | E13: Meeting of Two Worlds | G13: Chile | H13: CL
... A47: Holiday | B47: 46212 | C47: Thursday | D47: Yes | E47: Independence Day | G47: Argentina | H47: AR
A48: Regional Holiday | B48: 46228 | C48: Saturday | D48: No | E48: Holiday of Mendoza Province (depending on region) | F48: Mendoza | G48: Argentina | H48: AR
A49: Holiday | B49: 46251 | C49: Monday | D49: Yes | E49: Step to the Immortality of General José de San Martin | G49: Argentina | H49: AR
A50: Holiday | B50: 46307 | C50: Monday | D50: Yes | E50: Day of Respect for Cultural Diversity | G50: Argentina | H50: AR
A51: Holiday | B51: 46349 | C51: Monday | D51: Yes | E51: National Sovereignty Day | G51: Argentina | H51: AR
A52: Holiday | B52: 46364 | C52: Tuesday | D52: Yes | E52: Immaculate Conception of Mary | G52: Argentina | H52: AR
A53: Holiday | B53: 46381 | C53: Friday | D53: Yes | E53: Christmas Day | G53: Argentina | H53: AR
A54: Holiday | B54: 46023 | C54: Thursday | D54: Yes | E54: New Year’s Day | F54: All Entities | G54: United States of America | H54: US
A55: Holiday | B55: 46041 | C55: Monday | D55: Yes | E55: Martin Luther King, Jr.´s Birthday | F55: not EU51 | G55: United States of America | H55: US
A56: Holiday | B56: 46069 | C56: Monday | D56: Yes | E56: President´s day | F56: not EU51 | G56: United States of America | H56: US
A57: Holiday | B57: 46167 | C57: Monday | D57: Yes | E57: Memorial Day | F57: All Entities | G57: United States of America | H57: US
A58: Holiday | B58: 46192 | C58: Friday | D58: Yes | E58: Juneteenth National Ind. Day | F58: not EU51 | G58: United States of America | H58: US
A59: Holiday | B59: 46206 | C59: Friday | D59: Yes | E59: Independence Day | F59: All Entities | G59: United States of America | H59: US
A60: Holiday | B60: 46272 | C60: Monday | D60: Yes | E60: Labor Day | F60: All Entities | G60: United States of America | H60: US
A61: Holiday | B61: 46307 | C61: Monday | D61: Yes | E61: Columbus Day | F61: not EU51 | G61: United States of America | H61: US
A62: Holiday | B62: 46352 | C62: Thursday | D62: Yes | E62: Thanksgiving Day | F62: All Entities | G62: United States of America | H62: US
A63: Holiday | B63: 46353 | C63: Friday | D63: Yes | E63: Day After Thanksgiving Day | F63: not EU51 | G63: United States of America | H63: US
A64: Holiday | B64: 46381 | C64: Friday | D64: Yes | E64: Christmas Day | F64: All Entities | G64: United States of America | H64: US
A65: Holidays | B65: 46023 | C65: Thursday | D65: Yes | E65: New Year´s Day | F65: Mandatory | G65: India | H65: IN
... A83: Holidays | B83: 46381 | C83: Friday | D83: Yes | E83: Christmas | F83: Mandatory | G83: India | H83: IN
A84: Holiday | B84: 46023 | C84: Thursday | D84: Yes | E84: New Year's Day | G84: Mexico | H84: MX
A85: Holiday | B85: 46055 | C85: Monday | D85: Yes | E85: Constitution Day | G85: Mexico | H85: MX
A86: Holiday | B86: 46097 | C86: Monday | D86: Yes | E86: Benito Juarez Birth Day | G86: Mexico | H86: MX
A87: Holiday | B87: 46114 | C87: Thursday | D87: Yes | E87: Maundy Thursday | G87: Mexico | H87: MX
A88: Holiday | B88: 46115 | C88: Friday | D88: Yes | E88: Good Friday | G88: Mexico | H88: MX
A89: Holiday | B89: 46143 | C89: Friday | D89: Yes | E89: Labor Day | G89: Mexico | H89: MX
A90: Holiday | B90: 46152 | C90: Sunday | D90: No | E90: Mother's Day | G90: Mexico | H90: MX
...

Sheet Sprint 15 Jul15-Jul28
A1: ID | B1: Work Item Type | C1: Title | D1: Developer | E1: Assigned To | F1: State | G1: Tags | H1: Created Date | I1: Story Points (Estimated) | J1: Carry Over | K1: Sprint Start Date | L1: Sprint End Date | M1: Scope Creep Validation | N1: Commited | O1: Scope Creep Amount | P1: Done
A2: 704283 | B2: Story | C2: Validation: SCTASK0374791 | Legal/Compliance Request for Bulk PDF Generation of DSR Emails by Dealer and Date Range | D2: Ataul Khalique <coniubj@jmfamily.com> | E2: Ataul Khalique <coniubj@jmfamily.com> | F2: Done | H2: 45813.585 | I2: 3 | K2: =Velocity!$B$27 -> 46218 | L2: =Velocity!$C$27 -> 46231.999 | M2: =IF(K2<H2,"True","False") -> False | N2: =IF(M2="False",I2,"") -> 3 | O2: =IF(M2="True",I2,"") | P2: =IF(J2>0,"",I2) -> 3
A3: 735761 | B3: Story | C3: Spike: Investigate End-to-End Tracking for Platform Events | D3: Sebastian Perez <conlbqr@jmfamily.com> | E3: Sebastian Perez <conlbqr@jmfamily.com> | F3: Done | H3: 45861.498 | I3: 5 | K3: =Velocity!$B$27 -> 46218 | L3: =Velocity!$C$27 -> 46231.999 | M3: =IF(K3<H3,"True","False") -> False | N3: =IF(M3="False",I3,"") -> 5 | O3: =IF(M3="True",I3,"") | P3: =IF(J3>0,"",I3) -> 5
A4: 881577 | B4: Story | C4: [Tech Debt] Spike - Failed Flow Interviews ( 1 of 3 ) | D4: Mahika Agrawal <conjkak@jmfamily.com> | E4: Mahika Agrawal <conjkak@jmfamily.com> | F4: Done | H4: 46063.904 | I4: 1 | K4: =Velocity!$B$27 -> 46218 | L4: =Velocity!$C$27 -> 46231.999 | M4: =IF(K4<H4,"True","False") -> False | N4: =IF(M4="False",I4,"") -> 1 | O4: =IF(M4="True",I4,"") | P4: =IF(J4>0,"",I4) -> 1
A5: 931784 | B5: Story | C5: [Info] [Vulnerability Fix] Connected app scopes for this org in file Dynatrace | D5: Manish Raj <conuazh@jmfamily.com> | E5: Manish Raj <conuazh@jmfamily.com> | F5: Done | H5: 46127.51 | I5: 5 | K5: =Velocity!$B$27 -> 46218 | L5: =Velocity!$C$27 -> 46231.999 | M5: =IF(K5<H5,"True","False") -> False | N5: =IF(M5="False",I5,"") -> 5 | O5: =IF(M5="True",I5,"") | P5: =IF(J5>0,"",I5) -> 5
A6: 933951 | B6: Story | C6: [Low] [Vulnerability Fix] Spike - Public static resources may expose data | D6: Apala Sen <conjzwj@jmfamily.com> | E6: Apala Sen <conjzwj@jmfamily.com> | F6: Done | H6: 46129.236 | I6: 5 | K6: =Velocity!$B$27 -> 46218 | L6: =Velocity!$C$27 -> 46231.999 | M6: =IF(K6<H6,"True","False") -> False | N6: =IF(M6="False",I6,"") -> 5 | O6: =IF(M6="True",I6,"") | P6: =IF(J6>0,"",I6) -> 5
A7: 944354 | B7: Story | C7: 07/15/2026 | PROD Deployment | SF Platform- DigitSec and Incidents | D7: Manish Raj <conuazh@jmfamily.com> | E7: Manish Raj <conuazh@jmfamily.com> | F7: Done | G7: Admin; carry-over 26.14; ProdDeploy | H7: 46142.648 | I7: 5 | K7: =Velocity!$B$27 -> 46218 | L7: =Velocity!$C$27 -> 46231.999 | M7: =IF(K7<H7,"True","False") -> False | N7: =IF(M7="False",I7,"") -> 5 | O7: =IF(M7="True",I7,"") | P7: =IF(J7>0,"",I7) -> 5
A8: 957732 | B8: Story | C8: Spike: Salesforce Edge Network Mandatory Enablement Assessment (2026) | D8: Jacobo Salazar <contytk@jmfamily.com> | E8: Jacobo Salazar <contytk@jmfamily.com> | F8: Done | G8: Admin; carry-over 26.12; carry-over 26.13; carry-over 26.14 | H8: 46162.701 | I8: 2 | J8: 1 | K8: =Velocity!$B$27 -> 46218 | L8: =Velocity!$C$27 -> 46231.999 | M8: =IF(K8<H8,"True","False") -> False | N8: =IF(M8="False",I8,"") -> 2 | O8: =IF(M8="True",I8,"") | P8: =IF(J8>0,"",I8)
A9: 960470 | B9: Story | C9: [High*] [Vulnerability Fix] Cross Site Scripting in file pages/JMA_Reports_ACCT.page | D9: Apala Sen <conjzwj@jmfamily.com> | E9: Josh Wood <conadie@jmfamily.com> | F9: Done | G9: carry-over 26.13; carry-over 26.14; Dev; HIGH | H9: 46168.706 | I9: 3 | J9: 0 | K9: =Velocity!$B$27 -> 46218 | L9: =Velocity!$C$27 -> 46231.999 | M9: =IF(K9<H9,"True","False") -> False | N9: =IF(M9="False",I9,"") -> 3 | O9: =IF(M9="True",I9,"") | P9: =IF(J9>0,"",I9) -> 3
A10: 971930 | B10: Story | C10: Recurring: Salesforce KLO/Administration and Support ticket's Triage - Sprint 26.15 | D10: N/A | F10: Done | H10: 46184.606 | I10: 0 | K10: =Velocity!$B$27 -> 46218 | L10: =Velocity!$C$27 -> 46231.999 | M10: =IF(K10<H10,"True","False") -> False | N10: =IF(M10="False",I10,"") -> 0 | O10: =IF(M10="True",I10,"") | P10: =IF(J10>0,"",I10) -> 0
A11: 976504 | B11: Story | C11: Phishing - Resistant MFA Enforcement for Privileged Users (Implementation) | D11: Apala Sen <conjzwj@jmfamily.com> | E11: Apala Sen <conjzwj@jmfamily.com> | F11: Done | G11: carry-over 26.13; carry-over 26.14; Dev | H11: 46190.593 | I11: 3 | J11: 1 | K11: =Velocity!$B$27 -> 46218 | L11: =Velocity!$C$27 -> 46231.999 | M11: =IF(K11<H11,"True","False") -> False | N11: =IF(M11="False",I11,"") -> 3 | O11: =IF(M11="True",I11,"") | P11: =IF(J11>0,"",I11)
A12: 977929 | B12: Story | C12: [Zoom] - Key rotation to maintain seamless integration with SalesForce Lightning (UAT) | D12: Ignacio Toledo <conmcxf@jmfamily.com> | E12: Ignacio Toledo <conmcxf@jmfamily.com> | F12: Done | H12: 46191.414 | I12: 5 | K12: =Velocity!$B$27 -> 46218 | L12: =Velocity!$C$27 -> 46231.999 | M12: =IF(K12<H12,"True","False") -> False | N12: =IF(M12="False",I12,"") -> 5 | O12: =IF(M12="True",I12,"") | P12: =IF(J12>0,"",I12) -> 5
A13: 985324 | B13: Story | C13: Initial DevOps Setup: GitHub Org Configuration, IdP Mapping, and Salesforce Prod Integration - Version 2 | D13: Victor Cabrera <congize@jmfamily.com> | E13: Victor Cabrera <congize@jmfamily.com> | F13: Done | H13: 46202.506 | I13: 8 | K13: =Velocity!$B$27 -> 46218 | L13: =Velocity!$C$27 -> 46231.999 | M13: =IF(K13<H13,"True","False") -> False | N13: =IF(M13="False",I13,"") -> 8 | O13: =IF(M13="True",I13,"") | P13: =IF(J13>0,"",I13) -> 8
A14: 991692 | B14: Story | C14: Commvault Phase 1 - Verify the Settings for Salesforce Production Integration for Commvault Backup (UAT/PROD) | D14: Manish Raj <conuazh@jmfamily.com> | E14: Manish Raj <conuazh@jmfamily.com> | F14: Done | H14: 46210.347 | I14: 2 | K14: =Velocity!$B$27 -> 46218 | L14: =Velocity!$C$27 -> 46231.999 | M14: =IF(K14<H14,"True","False") -> False | N14: =IF(M14="False",I14,"") -> 2 | O14: =IF(M14="True",I14,"") | P14: =IF(J14>0,"",I14) -> 2
A15: 1003096 | B15: Story | C15: MIAW - Hypercare support | D15: Carlos Juarez <conkqse@jmfamily.com> | E15: Carlos Juarez <conkqse@jmfamily.com> | F15: Done | H15: 46218.426 | I15: 3 | K15: =Velocity!$B$27 -> 46218 | L15: =Velocity!$C$27 -> 46231.999 | M15: =IF(K15<H15,"True","False") -> True | N15: =IF(M15="False",I15,"") | O15: =IF(M15="True",I15,"") -> 3 | P15: =IF(J15>0,"",I15) -> 3
A16: 1004474 | B16: Story | C16: Setting up Custom URL for DealerSource 2.0 in UAT | D16: Manish Raj <conuazh@jmfamily.com> | E16: Manish Raj <conuazh@jmfamily.com> | F16: Done | H16: 46219.313 | I16: 1 | K16: =Velocity!$B$27 -> 46218 | L16: =Velocity!$C$27 -> 46231.999 | M16: =IF(K16<H16,"True","False") -> True | N16: =IF(M16="False",I16,"") | O16: =IF(M16="True",I16,"") -> 1 | P16: =IF(J16>0,"",I16) -> 1
A17: 1005118 | B17: Story | C17: Per asm RHT side of Dealer Portal is inoperative at this time | D17: Carlos Juarez <conkqse@jmfamily.com> | E17: Carlos Juarez <conkqse@jmfamily.com> | F17: Done | H17: 46219.571 | I17: 2 | K17: =Velocity!$B$27 -> 46218 | L17: =Velocity!$C$27 -> 46231.999 | M17: =IF(K17<H17,"True","False") -> True | N17: =IF(M17="False",I17,"") | O17: =IF(M17="True",I17,"") -> 2 | P17: =IF(J17>0,"",I17) -> 2
A18: 1005609 | B18: Story | C18: Production - MIAW User Stories: | D18: N/A | E18: felipe gonzalez <confjhw@jmfamily.com> | F18: Done | H18: 46220.34 | I18: 0 | K18: =Velocity!$B$27 -> 46218 | L18: =Velocity!$C$27 -> 46231.999 | M18: =IF(K18<H18,"True","False") -> True | N18: =IF(M18="False",I18,"") | O18: =IF(M18="True",I18,"") -> 0 | P18: =IF(J18>0,"",I18) -> 0
A19: 1006303 | B19: Story | C19: UAT Deployments - Sprint 26.15 | D19: Manish Raj <conuazh@jmfamily.com> | E19: Manish Raj <conuazh@jmfamily.com> | F19: Done | H19: 46223.124 | I19: 3 | K19: =Velocity!$B$27 -> 46218 | L19: =Velocity!$C$27 -> 46231.999 | M19: =IF(K19<H19,"True","False") -> True | N19: =IF(M19="False",I19,"") | O19: =IF(M19="True",I19,"") -> 3 | P19: =IF(J19>0,"",I19) -> 3
A20: 1006800 | B20: Story | C20: Asbury Portal System Admins cannot Add Users | D20: Apala Sen <conjzwj@jmfamily.com> | E20: Apala Sen <conjzwj@jmfamily.com> | F20: Done | H20: 46223.601 | I20: 2 | K20: =Velocity!$B$27 -> 46218 | L20: =Velocity!$C$27 -> 46231.999 | M20: =IF(K20<H20,"True","False") -> True | N20: =IF(M20="False",I20,"") | O20: =IF(M20="True",I20,"") -> 2 | P20: =IF(J20>0,"",I20) -> 2
A21: 1007131 | B21: Story | C21: Road ready hub receiving chats after hours | D21: Mahika Agrawal <conjkak@jmfamily.com> | E21: felipe gonzalez <confjhw@jmfamily.com> | F21: Done | H21: 46224.357 | I21: 3 | K21: =Velocity!$B$27 -> 46218 | L21: =Velocity!$C$27 -> 46231.999 | M21: =IF(K21<H21,"True","False") -> True | N21: =IF(M21="False",I21,"") | O21: =IF(M21="True",I21,"") -> 3 | P21: =IF(J21>0,"",I21) -> 3
A22: 1008018 | B22: Story | C22: ACR AccountShare - Record Insert Failed; Manual Action Needed | D22: Manish Raj <conuazh@jmfamily.com> | E22: Manish Raj <conuazh@jmfamily.com> | F22: Done | H22: 46225.265 | I22: 2 | K22: =Velocity!$B$27 -> 46218 | L22: =Velocity!$C$27 -> 46231.999 | M22: =IF(K22<H22,"True","False") -> True | N22: =IF(M22="False",I22,"") | O22: =IF(M22="True",I22,"") -> 2 | P22: =IF(J22>0,"",I22) -> 2
A23: 1008170 | B23: Story | C23: 07/22/2026 | ECHANGE | PROD Deployment | SF Platform | D23: Jacobo Salazar <contytk@jmfamily.com> | E23: Jacobo Salazar <contytk@jmfamily.com> | F23: Done | H23: 46225.383 | I23: 5 | K23: =Velocity!$B$27 -> 46218 | L23: =Velocity!$C$27 -> 46231.999 | M23: =IF(K23<H23,"True","False") -> True | N23: =IF(M23="False",I23,"") | O23: =IF(M23="True",I23,"") -> 5 | P23: =IF(J23>0,"",I23) -> 5
... A29: 1010978 | B29: Bug | C29: Download statements issue still persist in Dealer Source | D29: Carlos Juarez <conkqse@jmfamily.com> | E29: Carlos Juarez <conkqse@jmfamily.com> | F29: Done | H29: 46230.353 | I29: 3 | K29: =Velocity!$B$27 -> 46218 | L29: =Velocity!$C$27 -> 46231.999 | M29: =IF(K29<H29,"True","False") -> True | N29: =IF(M29="False",I29,"") | O29: =IF(M29="True",I29,"") -> 3 | P29: =IF(J29>0,"",I29) -> 3

Sheet Sprint 16 Jul29-Ago11
A1: ID | B1: Work Item Type | C1: Title | D1: Developer | E1: Assigned To | F1: State | G1: Tags | H1: Created Date | I1: Story Points (Estimated) | J1: Carry Over | K1: Sprint Start Date | L1: Sprint End Date | M1: Scope Creep Validation | P1: Done
A2: ID | B2: Work Item Type | C2: Title | D2: Developer | E2: Assigned To | F2: State | G2: Tags | H2: Created Date | I2: Story Points | J2: Carry Over | K2: Sprint Start Date | L2: Sprint End Date | M2: Scope Creep Validation | N2: Commited | O2: Scope Creep Amount
A3: 761286 | B3: Story | C3: SCTASK0389150 - DPM Contact Create Access Automation | D3: N/A | E3: felipe gonzalez <confjhw@jmfamily.com> | F3: Done | G3: Carry Over Last Sprint (COLS) | H3: 45889.434 | I3: 3 | K3: =Velocity!$B$28 -> 46232 | L3: =Velocity!$C$28 -> 46245.999 | M3: =IF(K3<H3,"True","False") -> False | N3: =IF(M3="False",I3,"") -> 3 | O3: =IF(M3="True",I3,"") | P3: =IF(J3>0,"",I3) -> 3
A4: 820263 | B4: Story | C4: Flosum Summer 26 Release Analysis | D4: Manish Raj <conuazh@jmfamily.com> | E4: Manish Raj <conuazh@jmfamily.com> | F4: Done | G4: Admin; Dev | H4: 45972.51 | I4: 5 | K4: =Velocity!$B$28 -> 46232 | L4: =Velocity!$C$28 -> 46245.999 | M4: =IF(K4<H4,"True","False") -> False | N4: =IF(M4="False",I4,"") -> 5 | O4: =IF(M4="True",I4,"") | P4: =IF(J4>0,"",I4) -> 5
A5: 906039 | B5: Story | C5: Restrict DealerSource Tabs and Features for Independent Repair Facility Permission Group | D5: Habib Hasbun <jmasgeo@jmfamily.com> | E5: Habib Hasbun <jmasgeo@jmfamily.com> | F5: Done | G5: Admin; Blocked | H5: 46094.016 | I5: 3 | K5: =Velocity!$B$28 -> 46232 | L5: =Velocity!$C$28 -> 46245.999 | M5: =IF(K5<H5,"True","False") -> False | N5: =IF(M5="False",I5,"") -> 3 | O5: =IF(M5="True",I5,"") | P5: =IF(J5>0,"",I5) -> 3
A6: 931780 | B6: Story | C6: [Info] [Vulnerability Fix] Connected app scopes for this org in file Mulesoft Integration | D6: Mahika Agrawal <conjkak@jmfamily.com> | E6: Mahika Agrawal <conjkak@jmfamily.com> | F6: Done | G6: Admin; INFO | H6: 46127.505 | I6: 8 | K6: =Velocity!$B$28 -> 46232 | L6: =Velocity!$C$28 -> 46245.999 | M6: =IF(K6<H6,"True","False") -> False | N6: =IF(M6="False",I6,"") -> 8 | O6: =IF(M6="True",I6,"") | P6: =IF(J6>0,"",I6) -> 8
A7: 932496 | B7: Story | C7: [Tech Debt] [Critical] [Vulnerability Fix] Custom Code Exposed on the Internet in file Saleforce Objects | F7: Done | G7: CRITICAL | H7: 46128.328 | I7: 5 | K7: =Velocity!$B$28 -> 46232 | L7: =Velocity!$C$28 -> 46245.999 | M7: =IF(K7<H7,"True","False") -> False | N7: =IF(M7="False",I7,"") -> 5 | O7: =IF(M7="True",I7,"") | P7: =IF(J7>0,"",I7) -> 5
A8: 965965 | B8: Story | C8: 07/29/2026 | PROD Deployment | SF Platform | D8: Jacobo Salazar <contytk@jmfamily.com> | E8: Jacobo Salazar <contytk@jmfamily.com> | F8: Done | G8: Admin; carry-over 26.15; ProdDeploy | H8: 46175.681 | I8: 5 | J8: 2 | K8: =Velocity!$B$28 -> 46232 | L8: =Velocity!$C$28 -> 46245.999 | M8: =IF(K8<H8,"True","False") -> False | N8: =IF(M8="False",I8,"") -> 5 | O8: =IF(M8="True",I8,"") | P8: =IF(J8>0,"",I8)
A9: 982967 | B9: Story | C9: [Tech Debt] Fix JMA Seminar Process Flow Status Transition Logic | D9: Mahika Agrawal <conjkak@jmfamily.com> | E9: Mahika Agrawal <conjkak@jmfamily.com> | F9: Done | G9: Admin; carry-over 26.14; carry-over 26.15 | H9: 46197.698 | I9: 5 | K9: =Velocity!$B$28 -> 46232 | L9: =Velocity!$C$28 -> 46245.999 | M9: =IF(K9<H9,"True","False") -> False | N9: =IF(M9="False",I9,"") -> 5 | O9: =IF(M9="True",I9,"") | P9: =IF(J9>0,"",I9) -> 5
A10: 984594 | B10: Story | C10: [Spike] Analyze SellingRelationship Date Synchronization Logic Between Salesforce Platform Events and Salesforce Backup View | D10: Ataul Khalique <coniubj@jmfamily.com> | E10: Ataul Khalique <coniubj@jmfamily.com> | F10: Done | G10: Dev; RELEVANT | H10: 46199.483 | I10: 5 | K10: =Velocity!$B$28 -> 46232 | L10: =Velocity!$C$28 -> 46245.999 | M10: =IF(K10<H10,"True","False") -> False | N10: =IF(M10="False",I10,"") -> 5 | O10: =IF(M10="True",I10,"") | P10: =IF(J10>0,"",I10) -> 5
A11: 1001693 | B11: Story | C11: Recurring: Salesforce KLO/Administration and Support ticket's Triage - Sprint 26.16 | D11: N/A | F11: Done | G11: Admin; Dev | H11: 46217.724 | I11: 0 | K11: =Velocity!$B$28 -> 46232 | L11: =Velocity!$C$28 -> 46245.999 | M11: =IF(K11<H11,"True","False") -> False | N11: =IF(M11="False",I11,"") -> 0 | O11: =IF(M11="True",I11,"") | P11: =IF(J11>0,"",I11) -> 0
A12: 1001695 | B12: Story | C12: 08/05/2026 | PROD Deployment | SF Platform | D12: Jacobo Salazar <contytk@jmfamily.com> | E12: Jacobo Salazar <contytk@jmfamily.com> | F12: Done | G12: Admin; ProdDeploy | H12: 46217.726 | I12: 5 | K12: =Velocity!$B$28 -> 46232 | L12: =Velocity!$C$28 -> 46245.999 | M12: =IF(K12<H12,"True","False") -> False | N12: =IF(M12="False",I12,"") -> 5 | O12: =IF(M12="True",I12,"") | P12: =IF(J12>0,"",I12) -> 5
A13: 1007382 | B13: Bug | C13: Dealer Source | Submit Claim menu is incorrectly displayed - Only UAT | D13: N/A | E13: julieth barrera <conqhvn@jmfamily.com> | F13: Done | G13: OnlyUAT | H13: 46224.524 | K13: =Velocity!$B$28 -> 46232 | L13: =Velocity!$C$28 -> 46245.999 | M13: =IF(K13<H13,"True","False") -> False | N13: =IF(M13="False",I13,"") -> 0 | O13: =IF(M13="True",I13,"") | P13: =IF(J13>0,"",I13) -> 0
A14: 1009575 | B14: Story | C14: Speech Analytics Integration - Research Audit Report Logging for CallMiner Integration Access | D14: Tomas Olivera <conkgku@jmfamily.com> | E14: Tomas Olivera <conkgku@jmfamily.com> | F14: Done | G14: Dev | H14: 46226.572 | I14: 2 | K14: =Velocity!$B$28 -> 46232 | L14: =Velocity!$C$28 -> 46245.999 | M14: =IF(K14<H14,"True","False") -> False | N14: =IF(M14="False",I14,"") -> 2 | O14: =IF(M14="True",I14,"") | P14: =IF(J14>0,"",I14) -> 2
A15: 1009998 | B15: Story | C15: Q3 - Phase 1 | Business Scope SF Release | Test Case Design | D15: N/A | E15: felipe gonzalez <confjhw@jmfamily.com> | F15: Done | H15: 46227.349 | I15: 0 | K15: =Velocity!$B$28 -> 46232 | L15: =Velocity!$C$28 -> 46245.999 | M15: =IF(K15<H15,"True","False") -> False | N15: =IF(M15="False",I15,"") -> 0 | O15: =IF(M15="True",I15,"") | P15: =IF(J15>0,"",I15) -> 0
A16: 1011379 | B16: Story | C16: GitHub Release Enablement - Unit Test Remediation - Dealer Source | D16: Carlos Juarez <conkqse@jmfamily.com> | E16: Carlos Juarez <conkqse@jmfamily.com> | F16: Done | G16: Dev | H16: 46230.605 | I16: 8 | K16: =Velocity!$B$28 -> 46232 | L16: =Velocity!$C$28 -> 46245.999 | M16: =IF(K16<H16,"True","False") -> False | N16: =IF(M16="False",I16,"") -> 8 | O16: =IF(M16="True",I16,"") | P16: =IF(J16>0,"",I16) -> 8
A17: 1011645 | B17: Story | C17: Account canonicals - AffiliationTerritoryCode, AffiliationRegionCore, and AffiliationManagerName not updating | D17: Sebastian Perez <conlbqr@jmfamily.com> | E17: Sebastian Perez <conlbqr@jmfamily.com> | F17: Done | G17: RELEVANT | H17: 46230.687 | I17: 8 | K17: =Velocity!$B$28 -> 46232 | L17: =Velocity!$C$28 -> 46245.999 | M17: =IF(K17<H17,"True","False") -> False | N17: =IF(M17="False",I17,"") -> 8 | O17: =IF(M17="True",I17,"") | P17: =IF(J17>0,"",I17) -> 8
A18: 1016190 | B18: Story | C18: UAT Support & Deployment Activities | D18: Manish Raj <conuazh@jmfamily.com> | E18: Manish Raj <conuazh@jmfamily.com> | F18: Done | H18: 46234.209 | I18: 5 | K18: =Velocity!$B$28 -> 46232 | L18: =Velocity!$C$28 -> 46245.999 | M18: =IF(K18<H18,"True","False") -> True | N18: =IF(M18="False",I18,"") | O18: =IF(M18="True",I18,"") -> 5 | P18: =IF(J18>0,"",I18) -> 5
A19: 1016347 | B19: Story | C19: Dealer Weatlh Tool - Experience report logs | D19: Ignacio Toledo <conmcxf@jmfamily.com> | E19: Ignacio Toledo <conmcxf@jmfamily.com> | F19: Done | H19: 46234.36 | I19: 2 | K19: =Velocity!$B$28 -> 46232 | L19: =Velocity!$C$28 -> 46245.999 | M19: =IF(K19<H19,"True","False") -> True | N19: =IF(M19="False",I19,"") | O19: =IF(M19="True",I19,"") -> 2 | P19: =IF(J19>0,"",I19) -> 2
A20: 1018644 | B20: Story | C20: Fix Apex compilation errors & test-class failures across affected classes | D20: Apala Sen <conjzwj@jmfamily.com> | E20: Apala Sen <conjzwj@jmfamily.com> | F20: Done | G20: Dev; RELEVANT | H20: 46238.583 | I20: 3 | K20: =Velocity!$B$28 -> 46232 | L20: =Velocity!$C$28 -> 46245.999 | M20: =IF(K20<H20,"True","False") -> True | N20: =IF(M20="False",I20,"") | O20: =IF(M20="True",I20,"") -> 3 | P20: =IF(J20>0,"",I20) -> 3
A21: 1020579 | B21: Bug | C21: [Dynatrace App Synthetics] - Http monitor local outage for HTTP monitor JMA - Salesforce - IPs Check | D21: Ignacio Toledo <conmcxf@jmfamily.com> | E21: Ignacio Toledo <conmcxf@jmfamily.com> | F21: Done | H21: 46240.576 | I21: 2 | K21: =Velocity!$B$28 -> 46232 | L21: =Velocity!$C$28 -> 46245.999 | M21: =IF(K21<H21,"True","False") -> True | N21: =IF(M21="False",I21,"") | O21: =IF(M21="True",I21,"") -> 2 | P21: =IF(J21>0,"",I21) -> 2

Sheet Sprint 17 Comit
A1: Commited
A2: ID | B2: Work Item Type | C2: Title | D2: Developer | E2: Assigned To | F2: State | G2: Tags | H2: Created Date | I2: Story Points | J2: Carry Over | K2: Sprint Start Date | L2: Sprint End Date | M2: Scope Creep Validation | O2: Scope Creep Amount
A3: 838699 | B3: Story | C3: [Spike] End-to-End Payload Traceability and Attribute Validation for Salesforce-to-Synapse Account Canonicals Integration | D3: Carlos Juarez <conkqse@jmfamily.com> | E3: Carlos Juarez <conkqse@jmfamily.com> | F3: In Progress | G3: carry-over 26.15; carry-over 26.16; Dev; RELEVANT | H3: 46002.419 | I3: 8 | J3: 3 | K3: =Velocity!$B$29 -> 46246 | L3: =Velocity!$C$29 -> 46259.999 | M3: =IF(K3<H3,"True","False") -> False | O3: =IF(M3="True",I3,"") | R3: =-SUM(J3:J30)+SUM(I3:I30) -> 105
A4: 931743 | B4: Story | C4: [Info] [Vulnerability Fix] Connected app scopes for this org in file Dealer Portal User | E4: Sakshi Vazarde <conuumx@jmfamily.com> | F4: In Progress | G4: Admin; Blocked; carry-over 26.14; carry-over 26.15; carry-over 26.16; INFO | H4: 46127.486 | I4: 5 | K4: =Velocity!$B$29 -> 46246 | L4: =Velocity!$C$29 -> 46259.999 | M4: =IF(K4<H4,"True","False") -> False | O4: =IF(M4="True",I4,"")
A5: 931776 | B5: Story | C5: [Info] [Vulnerability Fix] Connected app scopes for this org in file Dealer User Info | D5: Manish Raj <conuazh@jmfamily.com> | E5: Manish Raj <conuazh@jmfamily.com> | F5: In Progress | G5: Admin; INFO | H5: 46127.5 | I5: 5 | K5: =Velocity!$B$29 -> 46246 | L5: =Velocity!$C$29 -> 46259.999 | M5: =IF(K5<H5,"True","False") -> False | O5: =IF(M5="True",I5,"")
A6: 931789 | B6: Story | C6: [Info] [Vulnerability Fix] Connected app scopes for this org in file SAP CPQ | D6: Mahika Agrawal <conjkak@jmfamily.com> | E6: Mahika Agrawal <conjkak@jmfamily.com> | F6: In Progress | G6: Admin; INFO | H6: 46127.515 | I6: 8 | K6: =Velocity!$B$29 -> 46246 | L6: =Velocity!$C$29 -> 46259.999 | M6: =IF(K6<H6,"True","False") -> False | O6: =IF(M6="True",I6,"")
A7: 946206 | B7: Story | C7: [Low] [Vulnerability Fix] Public static resources may expose data | E7: felipe gonzalez <confjhw@jmfamily.com> | F7: In Progress | G7: carry-over 26.16; Dev; LOW | H7: 46147.385 | I7: 5 | K7: =Velocity!$B$29 -> 46246 | L7: =Velocity!$C$29 -> 46259.999 | M7: =IF(K7<H7,"True","False") -> False | O7: =IF(M7="True",I7,"")
A8: 959000 | B8: Story | C8: [Low] [Vulnerability Fix] Third Party Applications are connected to an admin user | D8: Jacobo Salazar <contytk@jmfamily.com> | E8: Jacobo Salazar <contytk@jmfamily.com> | F8: In Progress | G8: Admin; carry-over 26.16; LOW | H8: 46164.385 | I8: 5 | J8: 2 | K8: =Velocity!$B$29 -> 46246 | L8: =Velocity!$C$29 -> 46259.999 | M8: =IF(K8<H8,"True","False") -> False | O8: =IF(M8="True",I8,"")
A9: 965962 | B9: Story | C9: 08/19/2026 | PROD Deployment | SF Platform | D9: Jacobo Salazar <contytk@jmfamily.com> | E9: Jacobo Salazar <contytk@jmfamily.com> | F9: Done | G9: Admin; ProdDeploy | H9: 46175.68 | I9: 5 | K9: =Velocity!$B$29 -> 46246 | L9: =Velocity!$C$29 -> 46259.999 | M9: =IF(K9<H9,"True","False") -> False | O9: =IF(M9="True",I9,"")
A10: 984586 | B10: Story | C10: [Info] [Vulnerability Fix] Connected app scopes for this org in file JMSC Forum | D10: Ataul Khalique <coniubj@jmfamily.com> | E10: Ataul Khalique <coniubj@jmfamily.com> | F10: Done | G10: Admin; carry-over 26.16; INFO | H10: 46199.463 | I10: 5 | J10: 1 | K10: =Velocity!$B$29 -> 46246 | L10: =Velocity!$C$29 -> 46259.999 | M10: =IF(K10<H10,"True","False") -> False | O10: =IF(M10="True",I10,"")
A11: 989844 | B11: Story | C11: Create and Configure Salesforce Reference Sandbox for Integration Replication | D11: Apala Sen <conjzwj@jmfamily.com> | E11: Apala Sen <conjzwj@jmfamily.com> | F11: Ready for Sprint | G11: Dev | H11: 46205.356 | I11: 5 | K11: =Velocity!$B$29 -> 46246 | L11: =Velocity!$C$29 -> 46259.999 | M11: =IF(K11<H11,"True","False") -> False | O11: =IF(M11="True",I11,"")
A12: 991935 | B12: Story | C12: Commvault Phase 2 - Prepare Dedicated Salesforce Sandbox for Backup Validation | D12: Ignacio Toledo <conmcxf@jmfamily.com> | E12: Ignacio Toledo <conmcxf@jmfamily.com> | F12: In Progress | G12: Admin | H12: 46210.441 | I12: 8 | K12: =Velocity!$B$29 -> 46246 | L12: =Velocity!$C$29 -> 46259.999 | M12: =IF(K12<H12,"True","False") -> False | O12: =IF(M12="True",I12,"")
A13: 1001380 | B13: Story | C13: Fix API Error DSS - Authorize coupons in MTN Services | D13: Mahika Agrawal <conjkak@jmfamily.com> | E13: Mahika Agrawal <conjkak@jmfamily.com> | F13: Done | G13: Blocked; carry-over 26.15; Dev | H13: 46217.566 | I13: 3 | K13: =Velocity!$B$29 -> 46246 | L13: =Velocity!$C$29 -> 46259.999 | M13: =IF(K13<H13,"True","False") -> False | O13: =IF(M13="True",I13,"")
A14: 1001701 | B14: Story | C14: Recurring: Salesforce KLO/Administration and Support ticket's Triage - Sprint 26.17 | F14: Ready for Sprint | G14: Admin; Dev | H14: 46217.738 | I14: 13 | K14: =Velocity!$B$29 -> 46246 | L14: =Velocity!$C$29 -> 46259.999 | M14: =IF(K14<H14,"True","False") -> False | O14: =IF(M14="True",I14,"")
A15: 1004134 | B15: Story | C15: [SPIKE] Enhancement: Determine Workday -> SalesConnect Integration to Capture Associate Data | D15: Carlos Juarez <conkqse@jmfamily.com> | E15: Carlos Juarez <conkqse@jmfamily.com> | F15: In Progress | G15: Dev | H15: 46218.635 | I15: 5 | K15: =Velocity!$B$29 -> 46246 | L15: =Velocity!$C$29 -> 46259.999 | M15: =IF(K15<H15,"True","False") -> False | O15: =IF(M15="True",I15,"")
A16: 1004762 | B16: Story | C16: [Spike][Critical] AI-11 - Assess OAuth Migration for Named Credentials | D16: Ignacio Toledo <conmcxf@jmfamily.com> | E16: Ignacio Toledo <conmcxf@jmfamily.com> | F16: In Progress | G16: Admin | H16: 46219.418 | I16: 5 | K16: =Velocity!$B$29 -> 46246 | L16: =Velocity!$C$29 -> 46259.999 | M16: =IF(K16<H16,"True","False") -> False | O16: =IF(M16="True",I16,"")
A17: 1005763 | B17: Story | C17: [Spike] Investigate and resolve JMA_DEALER_ROLE__C canonical discrepancies between Salesforce and Synapse | D17: Ataul Khalique <coniubj@jmfamily.com> | E17: Ataul Khalique <coniubj@jmfamily.com> | F17: In Progress | G17: Dev; RELEVANT | H17: 46220.393 | I17: 5 | K17: =Velocity!$B$29 -> 46246 | L17: =Velocity!$C$29 -> 46259.999 | M17: =IF(K17<H17,"True","False") -> False | O17: =IF(M17="True",I17,"")
A18: 1006172 | B18: Story | C18: IT Request: Forms Issue – Missing VF Box / Excel Data Not Populating | D18: Santiago Epalza <conftst@jmfamily.com> | E18: Santiago Epalza <conftst@jmfamily.com> | F18: In Progress | G18: Dev | H18: 46220.646 | I18: 3 | K18: =Velocity!$B$29 -> 46246 | L18: =Velocity!$C$29 -> 46259.999 | M18: =IF(K18<H18,"True","False") -> False | O18: =IF(M18="True",I18,"")
A19: 1011559 | B19: Story | C19: GitHub Release Enablement - Unit Test Remediation - Sales connect | D19: Apala Sen <conjzwj@jmfamily.com> | E19: Apala Sen <conjzwj@jmfamily.com> | F19: Done | G19: carry-over 26.16; Dev | H19: 46230.637 | I19: 8 | J19: 1 | K19: =Velocity!$B$29 -> 46246 | L19: =Velocity!$C$29 -> 46259.999 | M19: =IF(K19<H19,"True","False") -> False | O19: =IF(M19="True",I19,"")
A20: 1014332 | B20: Story | C20: [Security & Compliance] Destination System Assessment and Integration Design for Salesforce Security Log Backup Retention | D20: Tomas Olivera <conkgku@jmfamily.com> | E20: Tomas Olivera <conkgku@jmfamily.com> | F20: In Progress | G20: carry-over 26.16; Dev | H20: 46232.494 | I20: 5 | K20: =Velocity!$B$29 -> 46246 | L20: =Velocity!$C$29 -> 46259.999 | M20: =IF(K20<H20,"True","False") -> False | O20: =IF(M20="True",I20,"")
A21: 1018654 | B21: Story | C21: Reconcile test-failure count discrepancy between PROD and existing sandboxes | D21: Apala Sen <conjzwj@jmfamily.com> | E21: Apala Sen <conjzwj@jmfamily.com> | F21: In Progress | G21: Dev | H21: 46238.585 | I21: 3 | K21: =Velocity!$B$29 -> 46246 | L21: =Velocity!$C$29 -> 46259.999 | M21: =IF(K21<H21,"True","False") -> False | O21: =IF(M21="True",I21,"")
A22: 1018843 | B22: Story | C22: Create one sandbox per product team (target 15–20 total) - Sales Enablement | D22: Jacobo Salazar <contytk@jmfamily.com> | E22: Jacobo Salazar <contytk@jmfamily.com> | F22: Ready for Sprint | G22: Admin | H22: 46238.74 | I22: 2 | J22: 2 | K22: =Velocity!$B$29 -> 46246 | L22: =Velocity!$C$29 -> 46259.999 | M22: =IF(K22<H22,"True","False") -> False | O22: =IF(M22="True",I22,"")
A23: 1019434 | B23: Story | C23: [Spike][Product Teams] Analyze Account type canonicals proposal and confirm readiness | E23: Gina Pardini <conjsji@jmfamily.com> | F23: In Progress | G23: BA; carry-over 26.16 | H23: 46239.54 | I23: 0 | K23: =Velocity!$B$29 -> 46246 | L23: =Velocity!$C$29 -> 46259.999 | M23: =IF(K23<H23,"True","False") -> False | O23: =IF(M23="True",I23,"")
A24: 1020034 | B24: Story | C24: [Spike] Define SF Platform Sandbox Testing Strategy (Automation Coverage + Test Plan) | E24: julieth barrera <conqhvn@jmfamily.com> | F24: In Progress | G24: Testing | H24: 46239.96 | I24: 0 | K24: =Velocity!$B$29 -> 46246 | L24: =Velocity!$C$29 -> 46259.999 | M24: =IF(K24<H24,"True","False") -> False | O24: =IF(M24="True",I24,"")
A25: 1020721 | B25: Story | C25: Cert Renewal for Mulesoft JWT jma-sf-mulesoft-jwt.jmfamily.com | D25: Ignacio Toledo <conmcxf@jmfamily.com> | E25: Ignacio Toledo <conmcxf@jmfamily.com> | F25: Done | G25: Admin; carry-over 26.16 | H25: 46240.704 | I25: 2 | J25: 1 | K25: =Velocity!$B$29 -> 46246 | L25: =Velocity!$C$29 -> 46259.999 | M25: =IF(K25<H25,"True","False") -> False | O25: =IF(M25="True",I25,"")
A26: 1022127 | B26: Story | C26: 08/12/2026 | PROD Deployment | SF Platform | D26: Ignacio Toledo <conmcxf@jmfamily.com> | E26: Ignacio Toledo <conmcxf@jmfamily.com> | F26: Done | G26: Admin; carry-over 26.16; ProdDeploy | H26: 46244.613 | I26: 3 | J26: 1 | K26: =Velocity!$B$29 -> 46246 | L26: =Velocity!$C$29 -> 46259.999 | M26: =IF(K26<H26,"True","False") -> False | O26: =IF(M26="True",I26,"")
A27: 1022744 | B27: Story | C27: DealerSource | Confirmation Pop-up Does Not Display the Action Button Correctly in Coupon Authorization | D27: Mahika Agrawal <conjkak@jmfamily.com> | E27: Mahika Agrawal <conjkak@jmfamily.com> | F27: In Progress | G27: Dev | H27: 46245.456 | I27: 3 | J27: 3 | K27: =Velocity!$B$29 -> 46246 | L27: =Velocity!$C$29 -> 46259.999 | M27: =IF(K27<H27,"True","False") -> False | O27: =IF(M27="True",I27,"")
A28: 1022796 | B28: Story | C28: UAT Support & Deployment Activities | D28: Manish Raj <conuazh@jmfamily.com> | E28: Manish Raj <conuazh@jmfamily.com> | F28: In Progress | G28: Admin | H28: 46245.494 | I28: 5 | J28: 5 | K28: =Velocity!$B$29 -> 46246 | L28: =Velocity!$C$29 -> 46259.999 | M28: =IF(K28<H28,"True","False") -> False | O28: =IF(M28="True",I28,"")
A29: 1022839 | B29: Story | C29: CallMiner / Speech Analytics Integration – Sprint Support Activities | D29: Tomas Olivera <conkgku@jmfamily.com> | E29: Tomas Olivera <conkgku@jmfamily.com> | F29: In Progress | G29: CallMinner; Dev | H29: 46245.506 | I29: 5 | J29: 5 | K29: =Velocity!$B$29 -> 46246 | L29: =Velocity!$C$29 -> 46259.999 | M29: =IF(K29<H29,"True","False") -> False | O29: =IF(M29="True",I29,"")
A30: 1023610 | B30: Story | C30: Create one sandbox per product team (target 15–20 total) - Digital Enablement | D30: Ignacio Toledo <conmcxf@jmfamily.com> | E30: Ignacio Toledo <conmcxf@jmfamily.com> | F30: Ready for Sprint | G30: Admin | H30: 46245.66 | I30: 2 | J30: 2 | K30: =Velocity!$B$29 -> 46246 | L30: =Velocity!$C$29 -> 46259.999 | M30: =IF(K30<H30,"True","False") -> False | O30: =IF(M30="True",I30,"")
A32: Actual
A33: ID | B33: Work Item Type | C33: Title | D33: Developer | E33: Assigned To | F33: State | G33: Tags | H33: Created Date | I33: Story Points (Estimated) | J33: Carry Over | K33: Sprint Start Date | L33: Sprint End Date | M33: Scope Creep Validation | N33: Commited | O33: Scope Creep Amount | P33: Done
A34: 989844 | B34: Story | C34: Create and Configure Salesforce Reference Sandbox for Integration Replication | D34: Apala Sen <conjzwj@jmfamily.com> | E34: Apala Sen <conjzwj@jmfamily.com> | F34: Ready for Sprint | G34: carry-over 26.17; Dev | H34: 46205.356 | I34: 5 | J34: 5 | K34: =Velocity!$B$29 -> 46246 | L34: =Velocity!$C$29 -> 46259.999 | M34: =IF(K34<H34,"True","False") -> False | N34: =IF(M34="False",I34,"") -> 5 | O34: =IF(M34="True",I34,"") | P34: =IF(J34>0,"",I34)
A35: 1011559 | B35: Story | C35: GitHub Release Enablement - Unit Test Remediation - Sales connect | D35: Apala Sen <conjzwj@jmfamily.com> | E35: Apala Sen <conjzwj@jmfamily.com> | F35: Done | G35: carry-over 26.16; Dev | H35: 46230.637 | I35: 8 | K35: =Velocity!$B$29 -> 46246 | L35: =Velocity!$C$29 -> 46259.999 | M35: =IF(K35<H35,"True","False") -> False | N35: =IF(M35="False",I35,"") -> 8 | O35: =IF(M35="True",I35,"") | P35: =IF(J35>0,"",I35) -> 8
A36: 1018654 | B36: Story | C36: Reconcile test-failure count discrepancy between PROD and existing sandboxes | D36: Apala Sen <conjzwj@jmfamily.com> | E36: Apala Sen <conjzwj@jmfamily.com> | F36: In Progress | G36: Dev | H36: 46238.585 | I36: 3 | K36: =Velocity!$B$29 -> 46246 | L36: =Velocity!$C$29 -> 46259.999 | M36: =IF(K36<H36,"True","False") -> False | N36: =IF(M36="False",I36,"") -> 3 | O36: =IF(M36="True",I36,"") | P36: =IF(J36>0,"",I36) -> 3
A37: 1026458 | B37: Story | C37: INC0633707 – Investigate and Resolve Territory Account Ownership Reassignment Issue (PROD) | D37: Apala Sen <conjzwj@jmfamily.com> | E37: Apala Sen <conjzwj@jmfamily.com> | F37: Done | G37: Dev | H37: 46248.544 | I37: 3 | K37: =Velocity!$B$29 -> 46246 | L37: =Velocity!$C$29 -> 46259.999 | M37: =IF(K37<H37,"True","False") -> True | N37: =IF(M37="False",I37,"") | O37: =IF(M37="True",I37,"") -> 3 | P37: =IF(J37>0,"",I37) -> 3
A38: 1026491 | B38: Story | C38: AccountTypeName Mapping – Current vs. Future State Analysis & Impact Validation Preparation | D38: Apala Sen <conjzwj@jmfamily.com> | E38: Apala Sen <conjzwj@jmfamily.com> | F38: Done | G38: Dev | H38: 46248.574 | I38: 5 | K38: =Velocity!$B$29 -> 46246 | L38: =Velocity!$C$29 -> 46259.999 | M38: =IF(K38<H38,"True","False") -> True | N38: =IF(M38="False",I38,"") | O38: =IF(M38="True",I38,"") -> 5 | P38: =IF(J38>0,"",I38) -> 5
A39: 1029130 | B39: Story | C39: Analysis: Online Claims needs access to Messaging Session record Transcripts | D39: Apala Sen <conjzwj@jmfamily.com> | E39: Apala Sen <conjzwj@jmfamily.com> | F39: Done | G39: Dev; NotImplement | H39: 46254.256 | I39: 3 | K39: =Velocity!$B$29 -> 46246 | L39: =Velocity!$C$29 -> 46259.999 | M39: =IF(K39<H39,"True","False") -> True | N39: =IF(M39="False",I39,"") | O39: =IF(M39="True",I39,"") -> 3 | P39: =IF(J39>0,"",I39) -> 3
A40: 1028259 | B40: Story | C40: Dealer Source | Modified Product Details are not getting updated through "Modify Product" button | D40: Ataul Khalique <coniubj@jmfamily.com> | E40: Ataul Khalique <coniubj@jmfamily.com> | F40: Removed | H40: 46253.25 | I40: 2 | K40: =Velocity!$B$29 -> 46246 | L40: =Velocity!$C$29 -> 46259.999 | M40: =IF(K40<H40,"True","False") -> True | N40: =IF(M40="False",I40,"") | O40: =IF(M40="True",I40,"") -> 2 | P40: =IF(J40>0,"",I40) -> 2
A41: 1031391 | B41: Story | C41: [SPIKE] Beqom: Investigate Null Account Number Values Impacting Dealer Data Processing | D41: Ataul Khalique <coniubj@jmfamily.com> | E41: Ataul Khalique <coniubj@jmfamily.com> | F41: Done | G41: Dev | H41: 46258.649 | I41: 5 | K41: =Velocity!$B$29 -> 46246 | L41: =Velocity!$C$29 -> 46259.999 | M41: =IF(K41<H41,"True","False") -> True | N41: =IF(M41="False",I41,"") | O41: =IF(M41="True",I41,"") -> 5 | P41: =IF(J41>0,"",I41) -> 5
...

Sheet Sprint 17 Ago12-Ago25
A1: ID | B1: Work Item Type | C1: Title | D1: Developer | E1: Assigned To | F1: State | G1: Tags | H1: Created Date | I1: Story Points (Estimated) | J1: Carry Over | K1: Sprint Start Date | L1: Sprint End Date | M1: Scope Creep Validation | N1: Commited | O1: Scope Creep Amount | P1: Done
A2: 989844 | B2: Story | C2: Create and Configure Salesforce Reference Sandbox for Integration Replication | D2: Apala Sen <conjzwj@jmfamily.com> | E2: Apala Sen <conjzwj@jmfamily.com> | F2: Ready for Sprint | G2: carry-over 26.17; Dev | H2: 46205.356 | I2: 5 | J2: 5 | K2: =Velocity!$B$29 -> 46246 | L2: =Velocity!$C$29 -> 46259.999 | M2: =IF(K2<H2,"True","False") -> False | N2: =IF(M2="False",I2,"") -> 5 | O2: =IF(M2="True",I2,"") | P2: =IF(J2>0,"",I2)
A3: 1011559 | B3: Story | C3: GitHub Release Enablement - Unit Test Remediation - Sales connect | D3: Apala Sen <conjzwj@jmfamily.com> | E3: Apala Sen <conjzwj@jmfamily.com> | F3: Done | G3: carry-over 26.16; Dev | H3: 46230.637 | I3: 8 | K3: =Velocity!$B$29 -> 46246 | L3: =Velocity!$C$29 -> 46259.999 | M3: =IF(K3<H3,"True","False") -> False | N3: =IF(M3="False",I3,"") -> 8 | O3: =IF(M3="True",I3,"") | P3: =IF(J3>0,"",I3) -> 8
A4: 1018654 | B4: Story | C4: Reconcile test-failure count discrepancy between PROD and existing sandboxes | D4: Apala Sen <conjzwj@jmfamily.com> | E4: Apala Sen <conjzwj@jmfamily.com> | F4: In Progress | G4: Dev | H4: 46238.585 | I4: 3 | K4: =Velocity!$B$29 -> 46246 | L4: =Velocity!$C$29 -> 46259.999 | M4: =IF(K4<H4,"True","False") -> False | N4: =IF(M4="False",I4,"") -> 3 | O4: =IF(M4="True",I4,"") | P4: =IF(J4>0,"",I4) -> 3
A5: 1026458 | B5: Story | C5: INC0633707 – Investigate and Resolve Territory Account Ownership Reassignment Issue (PROD) | D5: Apala Sen <conjzwj@jmfamily.com> | E5: Apala Sen <conjzwj@jmfamily.com> | F5: Done | G5: Dev | H5: 46248.544 | I5: 3 | K5: =Velocity!$B$29 -> 46246 | L5: =Velocity!$C$29 -> 46259.999 | M5: =IF(K5<H5,"True","False") -> True | N5: =IF(M5="False",I5,"") | O5: =IF(M5="True",I5,"") -> 3 | P5: =IF(J5>0,"",I5) -> 3
A6: 1026491 | B6: Story | C6: AccountTypeName Mapping – Current vs. Future State Analysis & Impact Validation Preparation | D6: Apala Sen <conjzwj@jmfamily.com> | E6: Apala Sen <conjzwj@jmfamily.com> | F6: Done | G6: Dev | H6: 46248.574 | I6: 5 | K6: =Velocity!$B$29 -> 46246 | L6: =Velocity!$C$29 -> 46259.999 | M6: =IF(K6<H6,"True","False") -> True | N6: =IF(M6="False",I6,"") | O6: =IF(M6="True",I6,"") -> 5 | P6: =IF(J6>0,"",I6) -> 5
A7: 1029130 | B7: Story | C7: Analysis: Online Claims needs access to Messaging Session record Transcripts | D7: Apala Sen <conjzwj@jmfamily.com> | E7: Apala Sen <conjzwj@jmfamily.com> | F7: Done | G7: Dev; NotImplement | H7: 46254.256 | I7: 3 | K7: =Velocity!$B$29 -> 46246 | L7: =Velocity!$C$29 -> 46259.999 | M7: =IF(K7<H7,"True","False") -> True | N7: =IF(M7="False",I7,"") | O7: =IF(M7="True",I7,"") -> 3 | P7: =IF(J7>0,"",I7) -> 3
A8: 1028259 | B8: Story | C8: Dealer Source | Modified Product Details are not getting updated through "Modify Product" button | D8: Ataul Khalique <coniubj@jmfamily.com> | E8: Ataul Khalique <coniubj@jmfamily.com> | F8: Removed | H8: 46253.25 | I8: 2 | K8: =Velocity!$B$29 -> 46246 | L8: =Velocity!$C$29 -> 46259.999 | M8: =IF(K8<H8,"True","False") -> True | N8: =IF(M8="False",I8,"") | O8: =IF(M8="True",I8,"") -> 2 | P8: =IF(J8>0,"",I8) -> 2
A9: 1031391 | B9: Story | C9: [SPIKE] Beqom: Investigate Null Account Number Values Impacting Dealer Data Processing | D9: Ataul Khalique <coniubj@jmfamily.com> | E9: Ataul Khalique <coniubj@jmfamily.com> | F9: Done | G9: Dev | H9: 46258.649 | I9: 5 | K9: =Velocity!$B$29 -> 46246 | L9: =Velocity!$C$29 -> 46259.999 | M9: =IF(K9<H9,"True","False") -> True | N9: =IF(M9="False",I9,"") | O9: =IF(M9="True",I9,"") -> 5 | P9: =IF(J9>0,"",I9) -> 5
A10: 1005763 | B10: Story | C10: [Spike] Investigate and resolve JMA_DEALER_ROLE__C canonical discrepancies between Salesforce and Synapse | D10: Ataul Khalique <coniubj@jmfamily.com> | E10: Ataul Khalique <coniubj@jmfamily.com> | F10: In Progress | G10: Dev; RELEVANT | H10: 46220.393 | I10: 5 | K10: =Velocity!$B$29 -> 46246 | L10: =Velocity!$C$29 -> 46259.999 | M10: =IF(K10<H10,"True","False") -> False | N10: =IF(M10="False",I10,"") -> 5 | O10: =IF(M10="True",I10,"") | P10: =IF(J10>0,"",I10) -> 5
A11: 984586 | B11: Story | C11: [Info] [Vulnerability Fix] Connected app scopes for this org in file JMSC Forum | D11: Ataul Khalique <coniubj@jmfamily.com> | E11: Ataul Khalique <coniubj@jmfamily.com> | F11: Done | G11: Admin; carry-over 26.16; INFO | H11: 46199.463 | I11: 5 | K11: =Velocity!$B$29 -> 46246 | L11: =Velocity!$C$29 -> 46259.999 | M11: =IF(K11<H11,"True","False") -> False | N11: =IF(M11="False",I11,"") -> 5 | O11: =IF(M11="True",I11,"") | P11: =IF(J11>0,"",I11) -> 5
A12: 931743 | B12: Story | C12: [Info] [Vulnerability Fix] Connected app scopes for this org in file Dealer Portal User | D12: Ataul Khalique <coniubj@jmfamily.com> | E12: Ataul Khalique <coniubj@jmfamily.com> | F12: Done | G12: Admin; Blocked; carry-over 26.14; carry-over 26.15; carry-over 26.16; INFO | H12: 46127.486 | I12: 5 | K12: =Velocity!$B$29 -> 46246 | L12: =Velocity!$C$29 -> 46259.999 | M12: =IF(K12<H12,"True","False") -> False | N12: =IF(M12="False",I12,"") -> 5 | O12: =IF(M12="True",I12,"") | P12: =IF(J12>0,"",I12) -> 5
A13: 838699 | B13: Story | C13: [Spike] End-to-End Payload Traceability and Attribute Validation for Salesforce-to-Synapse Account Canonicals Integration | D13: Carlos Juarez <conkqse@jmfamily.com> | E13: Carlos Juarez <conkqse@jmfamily.com> | F13: In Progress | G13: carry-over 26.15; carry-over 26.16; Dev; RELEVANT | H13: 46002.419 | I13: 8 | K13: =Velocity!$B$29 -> 46246 | L13: =Velocity!$C$29 -> 46259.999 | M13: =IF(K13<H13,"True","False") -> False | N13: =IF(M13="False",I13,"") -> 8 | O13: =IF(M13="True",I13,"") | P13: =IF(J13>0,"",I13) -> 8
A14: 1004134 | B14: Story | C14: [SPIKE] Enhancement: Determine Workday -> SalesConnect Integration to Capture Associate Data | D14: Carlos Juarez <conkqse@jmfamily.com> | E14: Carlos Juarez <conkqse@jmfamily.com> | F14: In Progress | G14: Dev | H14: 46218.635 | I14: 5 | K14: =Velocity!$B$29 -> 46246 | L14: =Velocity!$C$29 -> 46259.999 | M14: =IF(K14<H14,"True","False") -> False | N14: =IF(M14="False",I14,"") -> 5 | O14: =IF(M14="True",I14,"") | P14: =IF(J14>0,"",I14) -> 5
A15: 1019434 | B15: Story | C15: [Spike][Product Teams] Analyze Account type canonicals proposal and confirm readiness | D15: Gina Pardini <conjsji@jmfamily.com> | E15: Gina Pardini <conjsji@jmfamily.com> | F15: Done | G15: BA; carry-over 26.16 | H15: 46239.54 | I15: 0 | K15: =Velocity!$B$29 -> 46246 | L15: =Velocity!$C$29 -> 46259.999 | M15: =IF(K15<H15,"True","False") -> False | N15: =IF(M15="False",I15,"") -> 0 | O15: =IF(M15="True",I15,"") | P15: =IF(J15>0,"",I15) -> 0
A16: 1020721 | B16: Story | C16: Cert Renewal for Mulesoft JWT jma-sf-mulesoft-jwt.jmfamily.com | D16: Ignacio Toledo <conmcxf@jmfamily.com> | E16: Ignacio Toledo <conmcxf@jmfamily.com> | F16: Done | G16: Admin; carry-over 26.16 | H16: 46240.704 | I16: 2 | K16: =Velocity!$B$29 -> 46246 | L16: =Velocity!$C$29 -> 46259.999 | M16: =IF(K16<H16,"True","False") -> False | N16: =IF(M16="False",I16,"") -> 2 | O16: =IF(M16="True",I16,"") | P16: =IF(J16>0,"",I16) -> 2
A17: 1022127 | B17: Story | C17: 08/12/2026 | PROD Deployment | SF Platform | D17: Ignacio Toledo <conmcxf@jmfamily.com> | E17: Ignacio Toledo <conmcxf@jmfamily.com> | F17: Done | G17: Admin; carry-over 26.16; ProdDeploy | H17: 46244.613 | I17: 3 | K17: =Velocity!$B$29 -> 46246 | L17: =Velocity!$C$29 -> 46259.999 | M17: =IF(K17<H17,"True","False") -> False | N17: =IF(M17="False",I17,"") -> 3 | O17: =IF(M17="True",I17,"") | P17: =IF(J17>0,"",I17) -> 3
A18: 1023610 | B18: Story | C18: Create one sandbox per product team (target 15–20 total) - Digital Enablement | D18: Ignacio Toledo <conmcxf@jmfamily.com> | E18: Ignacio Toledo <conmcxf@jmfamily.com> | F18: Done | G18: Admin | H18: 46245.66 | I18: 2 | K18: =Velocity!$B$29 -> 46246 | L18: =Velocity!$C$29 -> 46259.999 | M18: =IF(K18<H18,"True","False") -> False | N18: =IF(M18="False",I18,"") -> 2 | O18: =IF(M18="True",I18,"") | P18: =IF(J18>0,"",I18) -> 2
A19: 1004762 | B19: Story | C19: [Spike][Critical] AI-11 - Assess OAuth Migration for Named Credentials | D19: Ignacio Toledo <conmcxf@jmfamily.com> | E19: Ignacio Toledo <conmcxf@jmfamily.com> | F19: Ready for Sprint | G19: Admin; carry-over 26.17 | H19: 46219.418 | I19: 5 | J19: 5 | K19: =Velocity!$B$29 -> 46246 | L19: =Velocity!$C$29 -> 46259.999 | M19: =IF(K19<H19,"True","False") -> False | N19: =IF(M19="False",I19,"") -> 5 | O19: =IF(M19="True",I19,"") | P19: =IF(J19>0,"",I19)
A20: 991935 | B20: Story | C20: Commvault Phase 2 - Prepare Dedicated Salesforce Sandbox for Backup Validation | D20: Ignacio Toledo <conmcxf@jmfamily.com> | E20: Ignacio Toledo <conmcxf@jmfamily.com> | F20: Done | G20: Admin | H20: 46210.441 | I20: 8 | K20: =Velocity!$B$29 -> 46246 | L20: =Velocity!$C$29 -> 46259.999 | M20: =IF(K20<H20,"True","False") -> False | N20: =IF(M20="False",I20,"") -> 8 | O20: =IF(M20="True",I20,"") | P20: =IF(J20>0,"",I20) -> 8
A21: 1031839 | B21: Story | C21: KB – Integration Certificate Renewal Process | D21: Ignacio Toledo <conmcxf@jmfamily.com> | E21: Ignacio Toledo <conmcxf@jmfamily.com> | F21: Done | G21: Admin | H21: 46259.401 | I21: 1 | K21: =Velocity!$B$29 -> 46246 | L21: =Velocity!$C$29 -> 46259.999 | M21: =IF(K21<H21,"True","False") -> True | N21: =IF(M21="False",I21,"") | O21: =IF(M21="True",I21,"") -> 1 | P21: =IF(J21>0,"",I21) -> 1
A22: 1027171 | B22: Story | C22: INC0645500 Unable to Access Salesforce DSS/UAT via Mobile App - UAT | D22: Ignacio Toledo <conmcxf@jmfamily.com> | E22: Ignacio Toledo <conmcxf@jmfamily.com> | F22: Done | G22: Admin | H22: 46251.65 | I22: 3 | K22: =Velocity!$B$29 -> 46246 | L22: =Velocity!$C$29 -> 46259.999 | M22: =IF(K22<H22,"True","False") -> True | N22: =IF(M22="False",I22,"") | O22: =IF(M22="True",I22,"") -> 3 | P22: =IF(J22>0,"",I22) -> 3
A23: 1028617 | B23: Bug | C23: Salesforce CLI Error (AuthCodeExchangeError) | D23: Ignacio Toledo <conmcxf@jmfamily.com> | E23: Ignacio Toledo <conmcxf@jmfamily.com> | F23: Done | H23: 46253.498 | I23: 3 | K23: =Velocity!$B$29 -> 46246 | L23: =Velocity!$C$29 -> 46259.999 | M23: =IF(K23<H23,"True","False") -> True | N23: =IF(M23="False",I23,"") | O23: =IF(M23="True",I23,"") -> 3 | P23: =IF(J23>0,"",I23) -> 3
A24: 959000 | B24: Story | C24: [Low] [Vulnerability Fix] Third Party Applications are connected to an admin user | D24: Jacobo Salazar <contytk@jmfamily.com> | E24: Jacobo Salazar <contytk@jmfamily.com> | F24: In Progress | G24: Admin; carry-over 26.16; carry-over 26.17; LOW | H24: 46164.385 | I24: 5 | J24: 2 | K24: =Velocity!$B$29 -> 46246 | L24: =Velocity!$C$29 -> 46259.999 | M24: =IF(K24<H24,"True","False") -> False | N24: =IF(M24="False",I24,"") -> 5 | O24: =IF(M24="True",I24,"") | P24: =IF(J24>0,"",I24)
A25: 965962 | B25: Story | C25: 08/19/2026 | PROD Deployment | SF Platform | D25: Jacobo Salazar <contytk@jmfamily.com> | E25: Jacobo Salazar <contytk@jmfamily.com> | F25: Done | G25: Admin; ProdDeploy | H25: 46175.68 | I25: 5 | K25: =Velocity!$B$29 -> 46246 | L25: =Velocity!$C$29 -> 46259.999 | M25: =IF(K25<H25,"True","False") -> False | N25: =IF(M25="False",I25,"") -> 5 | O25: =IF(M25="True",I25,"") | P25: =IF(J25>0,"",I25) -> 5
A26: 1018843 | B26: Story | C26: Create one sandbox per product team (target 15–20 total) - Sales Enablement | D26: Jacobo Salazar <contytk@jmfamily.com> | E26: Jacobo Salazar <contytk@jmfamily.com> | F26: Ready for Sprint | G26: Admin; carry-over 26.17 | H26: 46238.74 | I26: 2 | J26: 2 | K26: =Velocity!$B$29 -> 46246 | L26: =Velocity!$C$29 -> 46259.999 | M26: =IF(K26<H26,"True","False") -> False | N26: =IF(M26="False",I26,"") -> 2 | O26: =IF(M26="True",I26,"") | P26: =IF(J26>0,"",I26)
A27: 1006172 | B27: Story | C27: IT Request: Forms Issue – Missing VF Box / Excel Data Not Populating | D27: julieth barrera <conqhvn@jmfamily.com> | E27: julieth barrera <conqhvn@jmfamily.com> | F27: Done | G27: Dev | H27: 46220.646 | I27: 3 | K27: =Velocity!$B$29 -> 46246 | L27: =Velocity!$C$29 -> 46259.999 | M27: =IF(K27<H27,"True","False") -> False | N27: =IF(M27="False",I27,"") -> 3 | O27: =IF(M27="True",I27,"") | P27: =IF(J27>0,"",I27) -> 3
A28: 1020034 | B28: Story | C28: [Spike] Define SF Platform Sandbox Testing Strategy (Automation Coverage + Test Plan) | D28: julieth barrera <conqhvn@jmfamily.com> | E28: julieth barrera <conqhvn@jmfamily.com> | F28: Done | G28: Testing | H28: 46239.96 | I28: 0 | K28: =Velocity!$B$29 -> 46246 | L28: =Velocity!$C$29 -> 46259.999 | M28: =IF(K28<H28,"True","False") -> False | N28: =IF(M28="False",I28,"") -> 0 | O28: =IF(M28="True",I28,"") | P28: =IF(J28>0,"",I28) -> 0
A29: 931789 | B29: Story | C29: [Info] [Vulnerability Fix] Connected app scopes for this org in file SAP CPQ | D29: Mahika Agrawal <conjkak@jmfamily.com> | E29: julieth barrera <conqhvn@jmfamily.com> | F29: In Progress | G29: Admin; carry-over 26.17; INFO | H29: 46127.515 | I29: 8 | J29: 2 | K29: =Velocity!$B$29 -> 46246 | L29: =Velocity!$C$29 -> 46259.999 | M29: =IF(K29<H29,"True","False") -> False | N29: =IF(M29="False",I29,"") -> 8 | O29: =IF(M29="True",I29,"") | P29: =IF(J29>0,"",I29)
A30: 1001380 | B30: Story | C30: Fix API Error DSS - Authorize coupons in MTN Services | D30: Mahika Agrawal <conjkak@jmfamily.com> | E30: Mahika Agrawal <conjkak@jmfamily.com> | F30: Done | G30: Blocked; carry-over 26.15; Dev | H30: 46217.566 | I30: 3 | K30: =Velocity!$B$29 -> 46246 | L30: =Velocity!$C$29 -> 46259.999 | M30: =IF(K30<H30,"True","False") -> False | N30: =IF(M30="False",I30,"") -> 3 | O30: =IF(M30="True",I30,"") | P30: =IF(J30>0,"",I30) -> 3
A31: 1023907 | B31: Bug | C31: Dealer Source | Authorized button's label gets disappear after providing RO number on Contract Services | D31: Mahika Agrawal <conjkak@jmfamily.com> | E31: Mahika Agrawal <conjkak@jmfamily.com> | F31: In Progress | G31: carry-over 26.17 | H31: 46246.269 | I31: 2 | J31: 2 | K31: =Velocity!$B$29 -> 46246 | L31: =Velocity!$C$29 -> 46259.999 | M31: =IF(K31<H31,"True","False") -> True | N31: =IF(M31="False",I31,"") | O31: =IF(M31="True",I31,"") -> 2 | P31: =IF(J31>0,"",I31)
